<robot xmlns:xacro="http://www.ros.org/wiki/xacro" name="MyRobot">
    <xacro:include filename="baseInertial.xacro" />

    <link name="base_link">
        <xacro:basic_box mass="1." x="1." y="0.7" z="0.2" r="1" g="0" b="0">
            <origin xyz="0.3 0.0 0.0"/>
        </xacro:basic_box>
    </link>

    <link name="wheelL_link">
        <xacro:basic_cylinder mass=".5" radius=".2" length=".05" r="1" g="0" b="1">
            <origin xyz="0.0 0.0 0.0" rpy="1.5708 0 0.0"/>
        </xacro:basic_cylinder>
    </link>

    <link name="wheelR_link">
        <xacro:basic_cylinder mass=".5" radius=".2" length=".05" r="1" g="0" b="1">
            <origin xyz="0.0 0.0 0.0" rpy="-1.5708 0 0.0"/>
        </xacro:basic_cylinder>
    </link>

    <link name="head_link">
        <visual>
            <origin xyz="0.0 0.0 0.05" rpy="0.0 0.0 0.0"/>
            <geometry>
                <box size="0.10 0.20 0.10"/>
            </geometry>
            <material name="adsfk">
                <color rgba=".0 01.0 1.0 1.0"/>
                <texture filename=""/>
            </material>
        </visual>
        <xacro:basic_box mass=".4" x="0.1" y="0.20" z="0.1" r="0" g="1" b="1">
            <origin xyz="0. 0.0 0.05"/>
        </xacro:basic_box>
    </link>

    <link name="lidar_link">
        <xacro:basic_cylinder mass=".1" radius=".1" length=".2" r="0" g="1" b="1">
            <origin xyz="0.0 0.0 -0.05" rpy="0 0 0.0"/>
        </xacro:basic_cylinder>
    </link>

    <link name="IMU_link">
        <xacro:basic_cylinder mass=".1" radius=".1" length=".05" r="0" g="1" b="1">
            <origin xyz="0.0 0.0 -0.0" rpy="0 0 0.0"/>
        </xacro:basic_cylinder>
    </link>

    <joint name="base_wheelR_joint" type="continuous">
        <origin xyz="0.0 -0.4 0.0" rpy="0.0 0.0 0.0"/>
        <parent link="base_link"/>
        <child link="wheelR_link"/>
        <axis xyz="0.0 1.0 0.0"/>
    </joint>

    <joint name="base_wheelL_joint" type="continuous">
        <origin xyz="0.0 0.4 0.0" rpy="0.0 0.0 3.14159"/>
        <parent link="base_link"/>
        <child link="wheelL_link"/>
        <axis xyz="0.0 -1.0 0.0"/>
    </joint>

    <joint name="base_head_link" type="fixed">
        <origin xyz="0.70 0.0 -0.20" rpy="0.0 0.0 0.0"/>
        <parent link="base_link"/>
        <child link="head_link"/>

    </joint>
    <joint name="base_lidar_link" type="fixed">
        <origin xyz="0.60 0.0 0.25" rpy="0.0 0.0 0.0"/>
        <parent link="base_link"/>
        <child link="lidar_link"/>
    </joint>

    <joint name="base_IMU_link" type="fixed">
        <origin xyz="0.0 0.0 0.125" rpy="0.0 0.0 0.0"/>
        <parent link="base_link"/>
        <child link="IMU_link"/>
    </joint>

    <gazebo reference="base_link">
        <material> Gazebo/Red </material>
    </gazebo>
    <gazebo reference="wheelL_link">
        <material> Gazebo/Purple </material>
    </gazebo>
    <gazebo reference="wheelR_link">
        <material> Gazebo/Purple </material>
    </gazebo>
    <gazebo reference="head_link">
        <material> Gazebo/Orange </material>
    </gazebo>

    <gazebo>
        <plugin name="differential_drive_controller" filename="libgazebo_ros_diff_drive.so">
            <ros>
                <!-- <namespace>/br</namespace> -->
            </ros>

            <update_rate>30</update_rate>

            <!-- wheels -->
            <left_joint>base_wheelL_joint</left_joint>
            <right_joint>base_wheelR_joint</right_joint>

            <!-- kinematics -->
            <wheel_separation>0.75</wheel_separation>
            <wheel_diameter>0.4</wheel_diameter>

            <!-- limits -->
            <max_wheel_torque>20</max_wheel_torque>
            <max_wheel_acceleration>1.0</max_wheel_acceleration>

            <command_topic>cmd_vel</command_topic>

            <!-- output -->
            <publish_odom>true</publish_odom>
            <publish_odom_tf>true</publish_odom_tf>
            <publish_wheel_tf>true</publish_wheel_tf>

            <odometry_topic>odom</odometry_topic>
            <odometry_frame>odom</odometry_frame>
            <robot_base_frame>base_link</robot_base_frame>
        </plugin>
    </gazebo>

    <gazebo reference="lidar_link">
        <sensor type="gpu_ray" name="lidar_sensor">
            <ray>
                <scan>
                    <horizontal>
                        <samples>300</samples>
                        <resolution>1</resolution>
                        <min_angle>-3.141592</min_angle>
                        <max_angle>3.141592</max_angle>
                    </horizontal>
                </scan>
                <range>
                    <min>0.10</min>
                    <max>10.0</max>
                    <resolution>0.01</resolution>
                </range>
                <noise>
                    <type>gaussian</type>
                    <mean>0.0</mean>
                    <stddev>0.01</stddev>
                </noise>
            </ray>
            <update_rate>5</update_rate>
            <visualize>true</visualize>
            <plugin name="lidar" filename="libgazebo_ros_ray_sensor.so">
                <output_type>sensor_msgs/PointCloud2</output_type>
                <frame_name>lidar_link</frame_name>
            </plugin>
        </sensor>
    </gazebo>

    <gazebo reference="IMU_link">
        <sensor name="imu_sensor" type="imu">
        <plugin filename="libgazebo_ros_imu_sensor.so" name="imu_plugin">
            <ros>
                <namespace>/imu</namespace>
                <remapping>~/out:=out</remapping>
            </ros>
            <initial_orientation_as_reference>false</initial_orientation_as_reference>
            </plugin>
            <always_on>true</always_on>
            <update_rate>100</update_rate>
            <visualize>true</visualize>
            <imu>
            <angular_velocity>
                <x>
                <noise type="gaussian">
                    <mean>0.0</mean>
                    <stddev>2e-4</stddev>
                    <bias_mean>0.0000075</bias_mean>
                    <bias_stddev>0.0000008</bias_stddev>
                </noise>
                </x>
                <y>
                <noise type="gaussian">
                    <mean>0.0</mean>
                    <stddev>2e-4</stddev>
                    <bias_mean>0.0000075</bias_mean>
                    <bias_stddev>0.0000008</bias_stddev>
                </noise>
                </y>
                <z>
                <noise type="gaussian">
                    <mean>0.0</mean>
                    <stddev>2e-4</stddev>
                    <bias_mean>0.0000075</bias_mean>
                    <bias_stddev>0.0000008</bias_stddev>
                </noise>
                </z>
            </angular_velocity>
            <linear_acceleration>
                <x>
                <noise type="gaussian">
                    <mean>0.0</mean>
                    <stddev>1.7e-2</stddev>
                    <bias_mean>0.1</bias_mean>
                    <bias_stddev>0.001</bias_stddev>
                </noise>
                </x>
                <y>
                <noise type="gaussian">
                    <mean>0.0</mean>
                    <stddev>1.7e-2</stddev>
                    <bias_mean>0.1</bias_mean>
                    <bias_stddev>0.001</bias_stddev>
                </noise>
                </y>
                <z>
                <noise type="gaussian">
                    <mean>0.0</mean>
                    <stddev>1.7e-2</stddev>
                    <bias_mean>0.1</bias_mean>
                    <bias_stddev>0.001</bias_stddev>
                </noise>
                </z>
            </linear_acceleration>
            </imu>
        </sensor>
    </gazebo>

</robot>