<robot xmlns:xacro="http://www.ros.org/wiki/xacro" name="MyRobot">
    <xacro:include filename="baseInertial.xacro" />

    <link name="base_link">
        <xacro:basic_box mass="1." x="1." y="0.7" z="0.2" r="1" g="0" b="0">
            <origin xyz="0.3 0.0 0.0"/>
        </xacro:basic_box>
    </link>

    <link name="wheelL_link">
        <xacro:basic_cylinder mass=".5" radius=".2" length=".05" r="1" g="0" b="1">
            <origin xyz="0.0 0.0 0.0" rpy="1.5708 0 0.0"/>
        </xacro:basic_cylinder>
    </link>

    <link name="wheelR_link">
        <xacro:basic_cylinder mass=".5" radius=".2" length=".05" r="1" g="0" b="1">
            <origin xyz="0.0 0.0 0.0" rpy="-1.5708 0 0.0"/>
        </xacro:basic_cylinder>
    </link>

    <link name="head_link">
        <visual>
            <origin xyz="0.0 0.0 0.05" rpy="0.0 0.0 0.0"/>
            <geometry>
                <box size="0.10 0.20 0.10"/>
            </geometry>
            <material name="adsfk">
                <color rgba=".0 01.0 1.0 1.0"/>
                <texture filename=""/>
            </material>
        </visual>
        <xacro:basic_box mass=".4" x="0.1" y="0.20" z="0.1" r="0" g="1" b="1">
            <origin xyz="0. 0.0 0.05"/>
        </xacro:basic_box>
    </link>

    <joint name="base_wheelR_joint" type="continuous">
        <origin xyz="0.0 -0.4 0.0" rpy="0.0 0.0 0.0"/>
        <parent link="base_link"/>
        <child link="wheelR_link"/>
        <axis xyz="0.0 1.0 0.0"/>
    </joint>

    <joint name="base_wheelL_joint" type="continuous">
        <origin xyz="0.0 0.4 0.0" rpy="0.0 0.0 3.14159"/>
        <parent link="base_link"/>
        <child link="wheelL_link"/>
        <axis xyz="0.0 -1.0 0.0"/>
    </joint>

    <joint name="base_head_link" type="fixed">
        <origin xyz="0.70 0.0 -0.20" rpy="0.0 0.0 0.0"/>
        <parent link="base_link"/>
        <child link="head_link"/>
    </joint>
<!--
    <gazebo>
        <plugin name="gazebo_ros_joint_state_publisher" filename="libgazebo_ros_joint_state_publisher.so">
            <update_rate>1</update_rate>
            <joint_name>base_wheelL_joint</joint_name>
            <joint_name>base_wheelR_joint</joint_name>
        </plugin>
    </gazebo>
-->
    <gazebo reference="base_link">
        <material> Gazebo/Red </material>
    </gazebo>
    <gazebo reference="wheelL_link">
        <material> Gazebo/Purple </material>
    </gazebo>
    <gazebo reference="wheelR_link">
        <material> Gazebo/Purple </material>
    </gazebo>
    <gazebo reference="head_link">
        <material> Gazebo/Orange </material>
    </gazebo>

    <gazebo>
        <plugin name="differential_drive_controller" filename="libgazebo_ros_diff_drive.so">
            <ros>
                <!-- <namespace>/br</namespace> -->
            </ros>

            <update_rate>30</update_rate>

            <!-- wheels -->
            <left_joint>base_wheelL_joint</left_joint>
            <right_joint>base_wheelR_joint</right_joint>

            <!-- kinematics -->
            <wheel_separation>0.75</wheel_separation>
            <wheel_diameter>0.4</wheel_diameter>

            <!-- limits -->
            <max_wheel_torque>20</max_wheel_torque>
            <max_wheel_acceleration>1.0</max_wheel_acceleration>

            <command_topic>cmd_vel</command_topic>

            <!-- output -->
            <publish_odom>true</publish_odom>
            <publish_odom_tf>true</publish_odom_tf>
            <publish_wheel_tf>true</publish_wheel_tf>

            <odometry_topic>odom</odometry_topic>
            <odometry_frame>odom</odometry_frame>
            <robot_base_frame>base_link</robot_base_frame> 
        </plugin>
    </gazebo>
</robot>